Workbook
Name Alu_data: [1]ALUDATA!$D:$E
Name bctc: '[1]THIET DAT'!$I$34
Name CHIPHITAICHINH: '[1]CHI PHI TAI CHINH'!$I$22
Name cpct: '[1]THIET DAT'!$I$6
Name cpcty: '[1]THIET DAT'!$I$35
Name cpk: '[1]THIET DAT'!$I$38
Name DiengiaiPKCN50.65: '[1]PKCN-50+65'!$D:$E
Name DiengiaiPKCN55.93: '[1]PKCN-55+93'!$D:$E
Name diengiaivattu: [1]Banggiaphukien!$A:$A
Name dongiakinh: '[1]THIET DAT'!$D:$D
Name dongiavattu: [1]Banggiaphukien!$E:$E
Name donvivattu: [1]Banggiaphukien!$C:$C
Name dpbh: '[1]THIET DAT'!$I$37
Name dpp: '[1]THIET DAT'!$I$36
Name ghichuvattu: [1]Banggiaphukien!$F:$F
Name gn: '[1]THIET DAT'!$I$8
Name gn_cdl: '[1]THIET DAT'!$I$10
Name gn_cdmq: '[1]THIET DAT'!$I$9
Name gn_csb: '[1]THIET DAT'!$I$11
Name gn_csl: '[1]THIET DAT'!$I$12
Name gnt: '[1]THIET DAT'!$I$7
Name hp_kinh: '[1]THIET DAT'!$I$32
Name hp_nhom: '[1]THIET DAT'!$I$31
Name hp_vtk: '[1]THIET DAT'!$I$33
Name HS_CLTD: '[1]PHU KIEN CLTD'!$C$2
Name khuon: '[1]THIET DAT'!$I$4
Name MACUA: [1]BKL!$B:$B
Name makinh: '[1]THIET DAT'!$B:$B
Name MAPROFILE: [1]ALUDATA!$D:$D
Name mavattu: [1]Banggiaphukien!$B:$B
Name ncld: '[1]THIET DAT'!$I$15
Name ncldvkt: '[1]THIET DAT'!$I$22
Name ncsx_cdl: '[1]THIET DAT'!$I$40
Name ncsx_cdmq: '[1]THIET DAT'!$I$39
Name ncsx_csb: '[1]THIET DAT'!$I$41
Name ncsx_csl: '[1]THIET DAT'!$I$42
Name pkbls: [1]PKBLS!$E$3
Name pkcn50.65: '[1]PKCN-50+65'!$A$2
Name pkcn55.93: '[1]PKCN-55+93'!$A$2
Name pkvkt: [1]PKVKT!$E$3
Name SOLUONG: [1]BKL!$K:$K
Name tbtc: '[1]THIET DAT'!$I$5
Name tenkinh: '[1]THIET DAT'!$A:$A
Name TENPROFILE: [1]ALUDATA!$C:$C
Name vc: '[1]THIET DAT'!$I$2
Name vs: '[1]THIET DAT'!$I$3

Sheet CPHoanThien
A1: BẢNG DỰ TRÙ CHI PHÍ TÀI CHÍNH ĐẦU DỰ ÁN
A2: =DETAIL!A2 -> Dự án: GOLDEN CITY
A3: =DETAIL!A3 -> Hạng mục: NHÔM KÍNH
A4: STT | B4: DIỄN GIẢI | C4: TÊN CHI TIẾT VẬT LIỆU | D4: ĐƠN VỊ | E4: KHỐI LƯỢNG | F4: ĐƠN GIÁ (VNĐ/ĐƠN VỊ) | G4: TỔNG TIỀN (VNĐ) | H4: GHI CHÚ
A5: A | B5: DOANH THU (trước VAT ) | G5: =DETAIL!J52 -> 40774762000
A9: B | B9: TỔNG CHI PHÍ | E9: =SUBTOTAL(9,E10:E117) -> 588843.83 | G9: =SUBTOTAL(9,G10:G127) -> 3.1011632e+10
A10: B1. | B10: CHI PHÍ GIA CÔNG | E10: =SUBTOTAL(9,E11:E13) -> 9912 | F10: =IFERROR(G10/E10,0) -> 178910.41 | G10: =SUBTOTAL(9,G11:G13) -> 1773360000
B11: D.1 NHÂN CÔNG GIA CÔNG (CỬA ĐI LÙA) | D11: m2 | E11: 2268 | F11: =IF(ISERR(G11/E11)=TRUE,"",G11/E11) -> 180000 | G11: 408240000
B12: D.1 NHÂN CÔNG GIA CÔNG (CỬA ĐI MỞ QUAY) | D12: m2 | E12: 7116 | F12: =IF(ISERR(G12/E12)=TRUE,"",G12/E12) -> 178853.29 | G12: 1272720000
B13: D.1 NHÂN CÔNG GIA CÔNG (CỬA SỔ LÙA) | D13: m2 | E13: 528 | F13: =IF(ISERR(G13/E13)=TRUE,"",G13/E13) -> 175000 | G13: 92400000
A14: B2. | B14: CHI PHÍ LẮP ĐẶT | E14: =SUBTOTAL(9,E15:E18) -> 12156 | F14: =IFERROR(G14/E14,0) -> 270000 | G14: =SUBTOTAL(9,G15:G18) -> 3282120000
B15: D.3 NHÂN CÔNG LẮP ĐẶT (CỬA ĐI LÙA) | D15: m2 | E15: 2268 | F15: =IF(ISERR(G15/E15)=TRUE,"",G15/E15) -> 270000 | G15: 612360000
B16: D.3 NHÂN CÔNG LẮP ĐẶT (CỬA ĐI MỞ QUAY) | D16: m2 | E16: 7116 | F16: =IF(ISERR(G16/E16)=TRUE,"",G16/E16) -> 270000 | G16: 1921320000
B17: D.3 NHÂN CÔNG LẮP ĐẶT (CỬA SỔ LÙA) | D17: m2 | E17: 528 | F17: =IF(ISERR(G17/E17)=TRUE,"",G17/E17) -> 270000 | G17: 142560000
B18: D.3 NHÂN CÔNG LẮP ĐẶT (VÁCH KÍNH PHÒNG TẮM) | D18: m2 | E18: 2244 | F18: =IF(ISERR(G18/E18)=TRUE,"",G18/E18) -> 270000 | G18: 605880000
A19: B3. | B19: NHÂN CÔNG VỆ SINH | E19: =SUBTOTAL(9,E20:E23) -> 12156 | F19: =IFERROR(G19/E19,0) -> 30000 | G19: =SUBTOTAL(9,G20:G23) -> 364680000
B20: D.4 CHI PHÍ VỆ SINH (CỬA ĐI LÙA) | D20: m2 | E20: 2268 | F20: =IF(ISERR(G20/E20)=TRUE,"",G20/E20) -> 30000 | G20: 68040000
B21: D.4 CHI PHÍ VỆ SINH (CỬA ĐI MỞ QUAY) | D21: m2 | E21: 7116 | F21: =IF(ISERR(G21/E21)=TRUE,"",G21/E21) -> 30000 | G21: 213480000
B22: D.4 CHI PHÍ VỆ SINH (CỬA SỔ LÙA) | D22: m2 | E22: 528 | F22: =IF(ISERR(G22/E22)=TRUE,"",G22/E22) -> 30000 | G22: 15840000
B23: D.4 CHI PHÍ VỆ SINH (VÁCH KÍNH PHÒNG TẮM) | D23: m2 | E23: 2244 | F23: =IF(ISERR(G23/E23)=TRUE,"",G23/E23) -> 30000 | G23: 67320000
A24: B4. | B24: CHI PHÍ NHÔM | E24: =SUBTOTAL(9,E25:E57) -> 75048.791 | F24: =IFERROR(G24/E24,0) -> 114721.73 | G24: =SUBTOTAL(9,G25:G57) -> 8.6097269e+09
B25: ALWS-BK007-1 | C25: =IFERROR(INDEX(TENPROFILE,MATCH(B25,MAPROFILE,0)),"") -> Ke góc | D25: Kg | E25: 992.15364 | F25: =IF(ISERR(G25/E25)=TRUE,"",G25/E25) -> 98000 | G25: 97231057
B26: ALWS-BK010 | C26: =IFERROR(INDEX(TENPROFILE,MATCH(B26,MAPROFILE,0)),"") -> Ke góc khung cánh cửa sổ | D26: Kg | E26: 509.012 | F26: =IF(ISERR(G26/E26)=TRUE,"",G26/E26) -> 98000 | G26: 49883176
B27: F347 | C27: =IFERROR(INDEX(TENPROFILE,MATCH(B27,MAPROFILE,0)),"") -> Ke góc | D27: Kg | E27: 3145.555 | F27: =IF(ISERR(G27/E27)=TRUE,"",G27/E27) -> 98000 | G27: 3.0826439e+08
B28: WSAD-5007 | C28: =IFERROR(INDEX(TENPROFILE,MATCH(B28,MAPROFILE,0)),"") -> Nẹp kính | D28: Kg | E28: 3422.242 | F28: =IF(ISERR(G28/E28)=TRUE,"",G28/E28) -> 116300 | G28: 3.9800675e+08
B29: WSAD-5015 | C29: =IFERROR(INDEX(TENPROFILE,MATCH(B29,MAPROFILE,0)),"") -> Khung bao | D29: Kg | E29: 7509.9675 | F29: =IF(ISERR(G29/E29)=TRUE,"",G29/E29) -> 116300 | G29: 8.7340922e+08
B30: WSAD-5016 | C30: =IFERROR(INDEX(TENPROFILE,MATCH(B30,MAPROFILE,0)),"") -> Khung cánh mở ra | D30: Kg | E30: 17272.491 | F30: =IF(ISERR(G30/E30)=TRUE,"",G30/E30) -> 116300 | G30: 2.0087907e+09
B31: WSAD-5018 | C31: =IFERROR(INDEX(TENPROFILE,MATCH(B31,MAPROFILE,0)),"") -> Đố động | D31: Kg | E31: 1537.061 | F31: =IF(ISERR(G31/E31)=TRUE,"",G31/E31) -> 116300 | G31: 1.7876019e+08
B32: WSAD-5019 | C32: =IFERROR(INDEX(TENPROFILE,MATCH(B32,MAPROFILE,0)),"") -> Nẹp chân | D32: Kg | E32: 263.52872 | F32: =IF(ISERR(G32/E32)=TRUE,"",G32/E32) -> 116300 | G32: 30648390
B33: WSAD-5020 | C33: =IFERROR(INDEX(TENPROFILE,MATCH(B33,MAPROFILE,0)),"") -> Ngưỡng cửa | D33: Kg | E33: 1008.3038 | F33: =IF(ISERR(G33/E33)=TRUE,"",G33/E33) -> 116300 | G33: 1.1726573e+08
B34: WSAW-5001 | C34: =IFERROR(INDEX(TENPROFILE,MATCH(B34,MAPROFILE,0)),"") -> Khung bao cố định | D34: Kg | E34: 8698.6939 | F34: =IF(ISERR(G34/E34)=TRUE,"",G34/E34) -> 116300 | G34: 1.0116581e+09
B35: WSAW-5002 | C35: =IFERROR(INDEX(TENPROFILE,MATCH(B35,MAPROFILE,0)),"") -> Khung bao cửa sổ | D35: Kg | E35: 213.03456 | F35: =IF(ISERR(G35/E35)=TRUE,"",G35/E35) -> 116300 | G35: 24775919
B36: WSAW-5003 | C36: =IFERROR(INDEX(TENPROFILE,MATCH(B36,MAPROFILE,0)),"") -> Thanh trung gian | D36: Kg | E36: 1953.7968 | F36: =IF(ISERR(G36/E36)=TRUE,"",G36/E36) -> 116300 | G36: 2.2722656e+08
... B57: XF01687 | C57: =IFERROR(INDEX(TENPROFILE,MATCH(B57,MAPROFILE,0)),"") -> Ke khung cánh (hệ XingFa) | D57: Kg | E57: 350.0544 | F57: =IF(ISERR(G57/E57)=TRUE,"",G57/E57) -> 98000 | G57: 34305331
A58: B5. | B58: CHI PHÍ KÍNH | E58: =SUBTOTAL(9,E59:E64) -> 54176.455 | F58: =IFERROR(G58/E58,0) -> 88332.903 | G58: =SUBTOTAL(9,G59:G64) -> 4.7855635e+09
B59: bk | C59: =IF(B59="","",_xlfn.IFNA(INDEX(tenkinh,MATCH(B59,makinh,0),0),0)) -> Băng keo bảo vệ kính | D59: m2 | E59: 19912.303 | F59: =IF(ISERR(G59/E59)=TRUE,"",G59/E59) -> 10000 | G59: 1.9912303e+08
B60: k10cl | C60: =IF(B60="","",_xlfn.IFNA(INDEX(tenkinh,MATCH(B60,makinh,0),0),0)) -> Kính trắng cường lực dày 10mm | D60: m2 | E60: 8409.6961 | F60: =IF(ISERR(G60/E60)=TRUE,"",G60/E60) -> 441666.67 | G60: 3.7142824e+09
B61: k8cl | C61: =IF(B61="","",_xlfn.IFNA(INDEX(tenkinh,MATCH(B61,makinh,0),0),0)) -> Kính trắng cường lực dày 8mm | D61: m2 | E61: 1546.4555 | F61: =IF(ISERR(G61/E61)=TRUE,"",G61/E61) -> 353703.7 | G61: 5.4698704e+08
B62: khoanlo | C62: =IF(B62="","",_xlfn.IFNA(INDEX(tenkinh,MATCH(B62,makinh,0),0),0)) -> Khoan lỗ | D62: m2 | E62: 2163 | F62: =IF(ISERR(G62/E62)=TRUE,"",G62/E62) -> 5000 | G62: 10815000
B63: khoet | C63: =IF(B63="","",_xlfn.IFNA(INDEX(tenkinh,MATCH(B63,makinh,0),0),0)) -> Khoét lỗ | D63: m2 | E63: 11433 | F63: =IF(ISERR(G63/E63)=TRUE,"",G63/E63) -> 20000 | G63: 228660000
...

Sheet DETAIL
A2: Dự án: GOLDEN CITY
A3: Hạng mục: NHÔM KÍNH
A5: PHẦN B - BÁO GIÁ CHI TIẾT | H5: Số Tài Liệu | I5: Phiên Bản | J5: Ngày
H6: =[1]SUMMARY!$B$3 -> GD-CT/2022_05.01 | I6: 00 | J6: =TODAY() -> 45842
A8: STT | B8: Mô tả | C8: Ký hiệu | D8: Rộng (m) | E8: Cao (m) | F8: Đơn vị | G8: Số lượng | H8: Tổng cộng | I8: Đơn giá (VND) | J8: Thành tiền (VND)
A9: A | B9: CỬA SỔ LÙA | H9: =SUBTOTAL(9,H10:H13) -> 528 | J9: =SUBTOTAL(9,J10:J13) -> 1800384000
A10: =IFERROR(A9*1,0)+1 -> 1 | B10: ='CSL-50.01'!G3&CHAR(10)&'CSL-50.01'!G4&CHAR(10)&'CSL-50.01'!G5&CHAR(10)&'CSL-50.01'!G6 -> Cửa sổ lùa 2 cánh - Nhôm hệ Nova 50 - Kính trắng cường lực dày 8mm - Phụ kiện bánh xe đôi, khóa âm đồng bộ Draho | C10: CSL-50.01 | D10: ='CSL-50.01'!C6 -> 1.2 | E10: ='CSL-50.01'!C7 -> 0.6 | F10: m2 | G10: ='CSL-50.01'!F7 -> 100 | H10: =D10*E10*G10 -> 72 | I10: ='CSL-50.01'!F4 -> 4103000 | J10: =H10*I10 -> 295416000
A11: =IFERROR(A10*1,0)+1 -> 2 | B11: ='CSL-50.02'!G3&CHAR(10)&'CSL-50.02'!G4&CHAR(10)&'CSL-50.02'!G5&CHAR(10)&'CSL-50.02'!G6 -> Cửa sổ lùa 2 cánh + ô kính cố định - Nhôm hệ Nova 50 - Kính trắng cường lực dày 8mm - Phụ kiện bánh xe đôi, khóa âm đồng bộ Draho | C11: CSL-50.02 | D11: ='CSL-50.02'!C6 -> 1.2 | E11: ='CSL-50.02'!C7 -> 1.1 | F11: m2 | G11: ='CSL-50.02'!F7 -> 100 | H11: =D11*E11*G11 -> 132 | I11: ='CSL-50.02'!F4 -> 3409000 | J11: =H11*I11 -> 449988000
A12: =IFERROR(A11*1,0)+1 -> 3 | B12: ='CSL-50.03'!G3&CHAR(10)&'CSL-50.03'!G4&CHAR(10)&'CSL-50.03'!G5&CHAR(10)&'CSL-50.03'!G6 -> Cửa sổ lùa 2 cánh + ô kính cố định - Nhôm hệ Nova 50 - Kính trắng cường lực dày 8mm - Phụ kiện bánh xe đôi, khóa âm đồng bộ Draho | C12: CSL-50.03 | D12: ='CSL-50.03'!C6 -> 1.2 | E12: ='CSL-50.03'!C7 -> 1.1 | F12: m2 | G12: ='CSL-50.03'!F7 -> 100 | H12: =D12*E12*G12 -> 132 | I12: ='CSL-50.03'!F4 -> 3409000 | J12: =H12*I12 -> 449988000
A13: =IFERROR(A12*1,0)+1 -> 4 | B13: ='[1]CSL-50.04'!G3&CHAR(10)&'[1]CSL-50.04'!G4&CHAR(10)&'[1]CSL-50.04'!G5&CHAR(10)&'[1]CSL-50.04'!G6 -> Cửa sổ lùa 2 cánh + ô kính cố định - Nhôm hệ Nova 50 - Kính trắng cường lực dày 8mm - Phụ kiện bánh xe đôi, khóa âm đồng bộ Draho | C13: CSL-50.04 | D13: ='[1]CSL-50.04'!C6 -> 1.2 | E13: ='[1]CSL-50.04'!C7 -> 1.6 | F13: m2 | G13: ='[1]CSL-50.04'!F7 -> 100 | H13: =D13*E13*G13 -> 192 | I13: ='[1]CSL-50.04'!F4 -> 3151000 | J13: =H13*I13 -> 604992000
A14: B | B14: CỬA ĐI LÙA | H14: =SUBTOTAL(9,H15:H18) -> 2268 | J14: =SUBTOTAL(9,J15:J18) -> 6.805116e+09
A15: =IFERROR(A14*1,0)+1 -> 1 | B15: ='[1]CDL-65.01'!G3&CHAR(10)&'[1]CDL-65.01'!G4&CHAR(10)&'[1]CDL-65.01'!G5&CHAR(10)&'[1]CDL-65.01'!G6 -> Cửa đi lùa 2 cánh - Nhôm hệ Nova 65 - Kính trắng cường lực dày 10mm - Phụ kiện bánh xe đôi, tay nắm chữ D đồng bộ Draho | C15: CDL-65.01 | D15: ='[1]CDL-65.01'!C6 -> 1.8 | E15: ='[1]CDL-65.01'!C7 -> 2.2 | F15: m2 | G15: ='[1]CDL-65.01'!F7 -> 100 | H15: =D15*E15*G15 -> 396 | I15: ='[1]CDL-65.01'!F4 -> 3029000 | J15: =H15*I15 -> 1.199484e+09
A16: =IFERROR(A15*1,0)+1 -> 2 | B16: ='[1]CDL-65.02'!G3&CHAR(10)&'[1]CDL-65.02'!G4&CHAR(10)&'[1]CDL-65.02'!G5&CHAR(10)&'[1]CDL-65.02'!G6 -> Cửa đi lùa 2 cánh + ô kính cố định - Nhôm hệ Nova 65 - Kính trắng cường lực dày 10mm - Phụ kiện bánh xe đôi, tay nắm chữ D đồng bộ Draho | C16: CDL-65.02 | D16: ='[1]CDL-65.02'!C6 -> 1.8 | E16: ='[1]CDL-65.02'!C7 -> 2.7 | F16: m2 | G16: ='[1]CDL-65.02'!F7 -> 100 | H16: =D16*E16*G16 -> 486 | I16: ='[1]CDL-65.02'!F4 -> 2964000 | J16: =H16*I16 -> 1.440504e+09
A17: =IFERROR(A16*1,0)+1 -> 3 | B17: ='[1]CDL-65.03'!G3&CHAR(10)&'[1]CDL-65.03'!G4&CHAR(10)&'[1]CDL-65.03'!G5&CHAR(10)&'[1]CDL-65.03'!G6 -> Cửa đi lùa 4 cánh (2 ray) - Nhôm hệ Nova 65 - Kính trắng cường lực dày 10mm - Phụ kiện bánh xe đôi, tay nắm chữ D đồng bộ Draho | C17: CDL-65.03 | D17: ='[1]CDL-65.03'!C6 -> 3.6 | E17: ='[1]CDL-65.03'!C7 -> 2.2 | F17: m2 | G17: ='[1]CDL-65.03'!F7 -> 100 | H17: =D17*E17*G17 -> 792 | I17: ='[1]CDL-65.03'!F4 -> 2904000 | J17: =H17*I17 -> 2.299968e+09
A18: =IFERROR(A17*1,0)+1 -> 4 | B18: ='[1]CDL-65.04'!G3&CHAR(10)&'[1]CDL-65.04'!G4&CHAR(10)&'[1]CDL-65.04'!G5&CHAR(10)&'[1]CDL-65.04'!G6 -> Cửa đi lùa 3 cánh (3 ray) - Nhôm hệ Nova 65 - Kính trắng cường lực dày 10mm - Phụ kiện bánh xe đôi, tay nắm chữ D đồng bộ Draho | C18: CDL-65.04 | D18: ='[1]CDL-65.04'!C6 -> 2.7 | E18: ='[1]CDL-65.04'!C7 -> 2.2 | F18: m2 | G18: ='[1]CDL-65.04'!F7 -> 100 | H18: =D18*E18*G18 -> 594 | I18: ='[1]CDL-65.04'!F4 -> 3140000 | J18: =H18*I18 -> 1.86516e+09
A19: C | B19: CỬA ĐI MỞ QUAY | H19: =SUBTOTAL(9,H20:H43) -> 7116 | J19: =SUBTOTAL(9,J20:J43) -> 24044508000
A20: =IFERROR(A19*1,0)+1 -> 1 | B20: ='[1]CSB-50.01'!G3&CHAR(10)&'[1]CSB-50.01'!G4&CHAR(10)&'[1]CSB-50.01'!G5&CHAR(10)&'[1]CSB-50.01'!G6 -> Cửa sổ bật 1 cánh - Nhôm hệ Nova 50 - Kính trắng cường lực dày 8mm - Phụ kiện tay nắm, bản lề chữ A đồng bộ Draho | C20: CSB-50.01 | D20: ='[1]CSB-50.01'!C6 -> 0.8 | E20: ='[1]CSB-50.01'!C7 -> 0.8 | F20: m2 | G20: ='[1]CSB-50.01'!F7 -> 100 | H20: =D20*E20*G20 -> 64 | I20: ='[1]CSB-50.01'!F4 -> 3837000 | J20: =H20*I20 -> 2.45568e+08
A21: =IFERROR(A20*1,0)+1 -> 2 | B21: ='[1]CSB-50.02'!G3&CHAR(10)&'[1]CSB-50.02'!G4&CHAR(10)&'[1]CSB-50.02'!G5&CHAR(10)&'[1]CSB-50.02'!G6 -> Cửa sổ bật 1 cánh + ô kính cố định - Nhôm hệ Nova 50 - Kính trắng cường lực dày 8mm - Phụ kiện tay nắm, bản lề chữ A đồng bộ Draho | C21: CSB-50.02 | D21: ='[1]CSB-50.02'!C6 -> 0.8 | E21: ='[1]CSB-50.02'!C7 -> 1.2 | F21: m2 | G21: ='[1]CSB-50.02'!F7 -> 100 | H21: =D21*E21*G21 -> 96 | I21: ='[1]CSB-50.02'!F4 -> 3790000 | J21: =H21*I21 -> 363840000
A22: =IFERROR(A21*1,0)+1 -> 3 | B22: ='[1]CSB-50.03'!G3&CHAR(10)&'[1]CSB-50.03'!G4&CHAR(10)&'[1]CSB-50.03'!G5&CHAR(10)&'[1]CSB-50.03'!G6 -> Cửa sổ bật 1 cánh + ô kính cố định - Nhôm hệ Nova 50 - Kính trắng cường lực dày 8mm - Phụ kiện tay nắm, bản lề chữ A đồng bộ Draho | C22: CSB-50.03 | D22: ='[1]CSB-50.03'!C6 -> 1.2 | E22: ='[1]CSB-50.03'!C7 -> 0.8 | F22: m2 | G22: ='[1]CSB-50.03'!F7 -> 100 | H22: =D22*E22*G22 -> 96 | I22: ='[1]CSB-50.03'!F4 -> 3790000 | J22: =H22*I22 -> 363840000
A23: =IFERROR(A22*1,0)+1 -> 4 | B23: ='[1]CSB-50.04'!G3&CHAR(10)&'[1]CSB-50.04'!G4&CHAR(10)&'[1]CSB-50.04'!G5&CHAR(10)&'[1]CSB-50.04'!G6 -> Cửa sổ bật 1 cánh + ô kính cố định - Nhôm hệ Nova 50 - Kính trắng cường lực dày 8mm - Phụ kiện tay nắm, bản lề chữ A đồng bộ Draho | C23: CSB-50.04 | D23: ='[1]CSB-50.04'!C6 -> 0.8 | E23: ='[1]CSB-50.04'!C7 -> 1.8 | F23: m2 | G23: ='[1]CSB-50.04'!F7 -> 100 | H23: =D23*E23*G23 -> 144 | I23: ='[1]CSB-50.04'!F4 -> 3309000 | J23: =H23*I23 -> 4.76496e+08
A24: =IFERROR(A23*1,0)+1 -> 5 | B24: ='[1]CSB-50.05'!G3&CHAR(10)&'[1]CSB-50.05'!G4&CHAR(10)&'[1]CSB-50.05'!G5&CHAR(10)&'[1]CSB-50.05'!G6 -> Cửa sổ bật 1 cánh + ô kính cố định - Nhôm hệ Nova 50 - Kính trắng cường lực dày 8mm - Phụ kiện tay nắm, bản lề chữ A đồng bộ Draho | C24: CSB-50.05 | D24: ='[1]CSB-50.05'!C6 -> 1.2 | E24: ='[1]CSB-50.05'!C7 -> 1.2 | F24: m2 | G24: ='[1]CSB-50.05'!F7 -> 100 | H24: =D24*E24*G24 -> 144 | I24: ='[1]CSB-50.05'!F4 -> 3352000 | J24: =H24*I24 -> 482688000
A25: =IFERROR(A24*1,0)+1 -> 6 | B25: ='[1]CSB-50.06'!G3&CHAR(10)&'[1]CSB-50.06'!G4&CHAR(10)&'[1]CSB-50.06'!G5&CHAR(10)&'[1]CSB-50.06'!G6 -> Cửa sổ bật 1 cánh + ô kính cố định - Nhôm hệ Nova 50 - Kính trắng cường lực dày 8mm - Phụ kiện tay nắm, bản lề chữ A đồng bộ Draho | C25: CSB-50.06 | D25: ='[1]CSB-50.06'!C6 -> 1.6 | E25: ='[1]CSB-50.06'!C7 -> 1.2 | F25: m2 | G25: ='[1]CSB-50.06'!F7 -> 100 | H25: =D25*E25*G25 -> 192 | I25: ='[1]CSB-50.06'!F4 -> 3146000 | J25: =H25*I25 -> 604032000
A26: =IFERROR(A25*1,0)+1 -> 7 | B26: ='[1]CSB-50.07'!G3&CHAR(10)&'[1]CSB-50.07'!G4&CHAR(10)&'[1]CSB-50.07'!G5&CHAR(10)&'[1]CSB-50.07'!G6 -> Cửa sổ bật 2 cánh + ô kính cố định - Nhôm hệ Nova 50 - Kính trắng cường lực dày 8mm - Phụ kiện tay nắm, bản lề chữ A đồng bộ Draho | C26: CSB-50.07 | D26: ='[1]CSB-50.07'!C6 -> 2 | E26: ='[1]CSB-50.07'!C7 -> 1.6 | F26: m2 | G26: ='[1]CSB-50.07'!F7 -> 100 | H26: =D26*E26*G26 -> 320 | I26: ='[1]CSB-50.07'!F4 -> 3197000 | J26: =H26*I26 -> 1023040000
A27: =IFERROR(A26*1,0)+1 -> 8 | B27: ='[1]CSB-50.08'!G3&CHAR(10)&'[1]CSB-50.08'!G4&CHAR(10)&'[1]CSB-50.08'!G5&CHAR(10)&'[1]CSB-50.08'!G6 -> Cửa sổ bật 2 cánh - Nhôm hệ Nova 50 - Kính trắng cường lực dày 8mm - Phụ kiện tay nắm, bản lề chữ A đồng bộ Draho | C27: CSB-50.08 | D27: ='[1]CSB-50.08'!C6 -> 1.6 | E27: ='[1]CSB-50.08'!C7 -> 0.8 | F27: m2 | G27: ='[1]CSB-50.08'!F7 -> 100 | H27: =D27*E27*G27 -> 128 | I27: ='[1]CSB-50.08'!F4 -> 4176000 | J27: =H27*I27 -> 5.34528e+08
A28: =IFERROR(A27*1,0)+1 -> 9 | B28: ='[1]CSB-50.09'!G3&CHAR(10)&'[1]CSB-50.09'!G4&CHAR(10)&'[1]CSB-50.09'!G5&CHAR(10)&'[1]CSB-50.09'!G6 -> Cửa sổ bật 2 cánh - Nhôm hệ Nova 50 - Kính trắng cường lực dày 8mm - Phụ kiện tay nắm, bản lề chữ A đồng bộ Draho | C28: CSB-50.09 | D28: ='[1]CSB-50.09'!C6 -> 1.6 | E28: ='[1]CSB-50.09'!C7 -> 1.2 | F28: m2 | G28: ='[1]CSB-50.09'!F7 -> 100 | H28: =D28*E28*G28 -> 192 | I28: ='[1]CSB-50.09'!F4 -> 3586000 | J28: =H28*I28 -> 688512000
A29: =IFERROR(A28*1,0)+1 -> 10 | B29: ='[1]CSB-50.10'!G3&CHAR(10)&'[1]CSB-50.10'!G4&CHAR(10)&'[1]CSB-50.10'!G5&CHAR(10)&'[1]CSB-50.10'!G6 -> Cửa sổ bật 2 cánh - Nhôm hệ Nova 50 - Kính trắng cường lực dày 8mm - Phụ kiện tay nắm, bản lề chữ A đồng bộ Draho | C29: CSB-50.10 | D29: ='[1]CSB-50.10'!C6 -> 1.6 | E29: ='[1]CSB-50.10'!C7 -> 1.6 | F29: m2 | G29: ='[1]CSB-50.10'!F7 -> 100 | H29: =D29*E29*G29 -> 256 | I29: ='[1]CSB-50.10'!F4 -> 3231000 | J29: =H29*I29 -> 8.27136e+08
A30: =IFERROR(A29*1,0)+1 -> 11 | B30: ='[1]CDMQ-50.01'!G3&CHAR(10)&'[1]CDMQ-50.01'!G4&CHAR(10)&'[1]CDMQ-50.01'!G5&CHAR(10)&'[1]CDMQ-50.01'!G6 -> Cửa đi mở quay 1 cánh - Nhôm hệ Nova 50 - Kính trắng cường lực dày 10mm - Phụ kiện bản lề 3D, thân khóa đa điểm đồng bộ Draho | C30: CDMQ-50.01 | D30: ='[1]CDMQ-50.01'!C6 -> 0.9 | E30: ='[1]CDMQ-50.01'!C7 -> 2.2 | F30: m2 | G30: ='[1]CDMQ-50.01'!F7 -> 100 | H30: =D30*E30*G30 -> 198 | I30: ='[1]CDMQ-50.01'!F4 -> 3619000 | J30: =H30*I30 -> 7.16562e+08
A31: =IFERROR(A30*1,0)+1 -> 12 | B31: ='[1]CDMQ-50.02'!G3&CHAR(10)&'[1]CDMQ-50.02'!G4&CHAR(10)&'[1]CDMQ-50.02'!G5&CHAR(10)&'[1]CDMQ-50.02'!G6 -> Cửa đi mở quay 1 cánh - Nhôm hệ Nova 50 - Kính trắng cường lực dày 10mm - Phụ kiện bản lề 3D, thân khóa đa điểm đồng bộ Draho | C31: CDMQ-50.02 | D31: ='[1]CDMQ-50.02'!C6 -> 0.9 | E31: ='[1]CDMQ-50.02'!C7 -> 2.2 | F31: m2 | G31: ='[1]CDMQ-50.02'!F7 -> 100 | H31: =D31*E31*G31 -> 198 | I31: ='[1]CDMQ-50.02'!F4 -> 3722000 | J31: =H31*I31 -> 7.36956e+08
A32: =IFERROR(A31*1,0)+1 -> 13 | B32: ='[1]CDMQ-50.03'!G3&CHAR(10)&'[1]CDMQ-50.03'!G4&CHAR(10)&'[1]CDMQ-50.03'!G5&CHAR(10)&'[1]CDMQ-50.03'!G6 -> Cửa đi mở quay 1 cánh + ô kính cố định - Nhôm hệ Nova 50 - Kính trắng cường lực dày 10mm - Phụ kiện bản lề 3D, thân khóa đa điểm đồng bộ Draho | C32: CDMQ-50.03 | D32: ='[1]CDMQ-50.03'!C6 -> 0.9 | E32: ='[1]CDMQ-50.03'!C7 -> 2.7 | F32: m2 | G32: ='[1]CDMQ-50.03'!F7 -> 100 | H32: =D32*E32*G32 -> 243 | I32: ='[1]CDMQ-50.03'!F4 -> 3470000 | J32: =H32*I32 -> 8.4321e+08
A33: =IFERROR(A32*1,0)+1 -> 14 | B33: ='[1]CDMQ-50.04'!G3&CHAR(10)&'[1]CDMQ-50.04'!G4&CHAR(10)&'[1]CDMQ-50.04'!G5&CHAR(10)&'[1]CDMQ-50.04'!G6 -> Cửa đi mở quay 1 cánh + ô kính cố định - Nhôm hệ Nova 50 - Kính trắng cường lực dày 10mm - Phụ kiện bản lề 3D, thân khóa đa điểm đồng bộ Draho | C33: CDMQ-50.04 | D33: ='[1]CDMQ-50.04'!C6 -> 0.9 | E33: ='[1]CDMQ-50.04'!C7 -> 2.7 | F33: m2 | G33: ='[1]CDMQ-50.04'!F7 -> 100 | H33: =D33*E33*G33 -> 243 | I33: ='[1]CDMQ-50.04'!F4 -> 3554000 | J33: =H33*I33 -> 8.63622e+08
A34: =IFERROR(A33*1,0)+1 -> 15 | B34: ='[1]CDMQ-50.05'!G3&CHAR(10)&'[1]CDMQ-50.05'!G4&CHAR(10)&'[1]CDMQ-50.05'!G5&CHAR(10)&'[1]CDMQ-50.05'!G6 -> Cửa đi mở quay 1 cánh + ô kính cố định - Nhôm hệ Nova 50 - Kính trắng cường lực dày 10mm - Phụ kiện bản lề 3D, thân khóa đa điểm đồng bộ Draho | C34: CDMQ-50.05 | D34: ='[1]CDMQ-50.05'!C6 -> 1.5 | E34: ='[1]CDMQ-50.05'!C7 -> 2.2 | F34: m2 | G34: ='[1]CDMQ-50.05'!F7 -> 100 | H34: =D34*E34*G34 -> 330 | I34: ='[1]CDMQ-50.05'!F4 -> 3139000 | J34: =H34*I34 -> 1035870000
A35: =IFERROR(A34*1,0)+1 -> 16 | B35: ='[1]CDMQ-50.06'!G3&CHAR(10)&'[1]CDMQ-50.06'!G4&CHAR(10)&'[1]CDMQ-50.06'!G5&CHAR(10)&'[1]CDMQ-50.06'!G6 -> Cửa đi mở quay 1 cánh + ô kính cố định - Nhôm hệ Nova 50 - Kính trắng cường lực dày 10mm - Phụ kiện bản lề 3D, thân khóa đa điểm đồng bộ Draho | C35: CDMQ-50.06 | D35: ='[1]CDMQ-50.06'!C6 -> 1.5 | E35: ='[1]CDMQ-50.06'!C7 -> 2.2 | F35: m2 | G35: ='[1]CDMQ-50.06'!F7 -> 100 | H35: =D35*E35*G35 -> 330 | I35: ='[1]CDMQ-50.06'!F4 -> 3202000 | J35: =H35*I35 -> 1056660000
A36: =IFERROR(A35*1,0)+1 -> 17 | B36: ='[1]CDMQ-50.07'!G3&CHAR(10)&'[1]CDMQ-50.07'!G4&CHAR(10)&'[1]CDMQ-50.07'!G5&CHAR(10)&'[1]CDMQ-50.07'!G6 -> Cửa đi mở quay 2 cánh - Nhôm hệ Nova 50 - Kính trắng cường lực dày 10mm - Phụ kiện bản lề 3D, thân khóa đa điểm đồng bộ Draho | C36: CDMQ-50.07 | D36: ='[1]CDMQ-50.07'!C6 -> 1.6 | E36: ='[1]CDMQ-50.07'!C7 -> 2.2 | F36: m2 | G36: ='[1]CDMQ-50.07'!F7 -> 100 | H36: =D36*E36*G36 -> 352 | I36: ='[1]CDMQ-50.07'!F4 -> 3472000 | J36: =H36*I36 -> 1.222144e+09
A37: =IFERROR(A36*1,0)+1 -> 18 | B37: ='[1]CDMQ-50.08'!G3&CHAR(10)&'[1]CDMQ-50.08'!G4&CHAR(10)&'[1]CDMQ-50.08'!G5&CHAR(10)&'[1]CDMQ-50.08'!G6 -> Cửa đi mở quay 2 cánh - Nhôm hệ Nova 50 - Kính trắng cường lực dày 10mm - Phụ kiện bản lề 3D, thân khóa đa điểm đồng bộ Draho | C37: CDMQ-50.08 | D37: ='[1]CDMQ-50.08'!C6 -> 1.6 | E37: ='[1]CDMQ-50.08'!C7 -> 2.2 | F37: m2 | G37: ='[1]CDMQ-50.08'!F7 -> 100 | H37: =D37*E37*G37 -> 352 | I37: ='[1]CDMQ-50.08'!F4 -> 3582000 | J37: =H37*I37 -> 1.260864e+09
A38: =IFERROR(A37*1,0)+1 -> 19 | B38: ='[1]CDMQ-50.09'!G3&CHAR(10)&'[1]CDMQ-50.09'!G4&CHAR(10)&'[1]CDMQ-50.09'!G5&CHAR(10)&'[1]CDMQ-50.09'!G6 -> Cửa đi mở quay 2 cánh + ô kính cố định - Nhôm hệ Nova 50 - Kính trắng cường lực dày 10mm - Phụ kiện bản lề 3D, thân khóa đa điểm đồng bộ Draho | C38: CDMQ-50.09 | D38: ='[1]CDMQ-50.09'!C6 -> 1.6 | E38: ='[1]CDMQ-50.09'!C7 -> 2.7 | F38: m2 | G38: ='[1]CDMQ-50.09'!F7 -> 100 | H38: =D38*E38*G38 -> 432 | I38: ='[1]CDMQ-50.09'!F4 -> 3312000 | J38: =H38*I38 -> 1430784000
A39: =IFERROR(A38*1,0)+1 -> 20 | B39: ='[1]CDMQ-50.10'!G3&CHAR(10)&'[1]CDMQ-50.10'!G4&CHAR(10)&'[1]CDMQ-50.10'!G5&CHAR(10)&'[1]CDMQ-50.10'!G6 -> Cửa đi mở quay 2 cánh + ô kính cố định - Nhôm hệ Nova 50 - Kính trắng cường lực dày 10mm - Phụ kiện bản lề 3D, thân khóa đa điểm đồng bộ Draho | C39: CDMQ-50.10 | D39: ='[1]CDMQ-50.10'!C6 -> 1.6 | E39: ='[1]CDMQ-50.10'!C7 -> 2.7 | F39: m2 | G39: ='[1]CDMQ-50.10'!F7 -> 100 | H39: =D39*E39*G39 -> 432 | I39: ='[1]CDMQ-50.10'!F4 -> 3402000 | J39: =H39*I39 -> 1469664000
A40: =IFERROR(A39*1,0)+1 -> 21 | B40: ='[1]CDMQ-50.11'!G3&CHAR(10)&'[1]CDMQ-50.11'!G4&CHAR(10)&'[1]CDMQ-50.11'!G5&CHAR(10)&'[1]CDMQ-50.11'!G6 -> Cửa đi mở quay 2 cánh + ô kính cố định - Nhôm hệ Nova 50 - Kính trắng cường lực dày 10mm - Phụ kiện bản lề 3D, thân khóa đa điểm đồng bộ Draho | C40: CDMQ-50.11 | D40: ='[1]CDMQ-50.11'!C6 -> 2.6 | E40: ='[1]CDMQ-50.11'!C7 -> 2.2 | F40: m2 | G40: ='[1]CDMQ-50.11'!F7 -> 100 | H40: =D40*E40*G40 -> 572 | I40: ='[1]CDMQ-50.11'!F4 -> 3111000 | J40: =H40*I40 -> 1.779492e+09
A41: =IFERROR(A40*1,0)+1 -> 22 | B41: ='[1]CDMQ-50.12'!G3&CHAR(10)&'[1]CDMQ-50.12'!G4&CHAR(10)&'[1]CDMQ-50.12'!G5&CHAR(10)&'[1]CDMQ-50.12'!G6 -> Cửa đi mở quay 2 cánh + ô kính cố định - Nhôm hệ Nova 50 - Kính trắng cường lực dày 10mm - Phụ kiện bản lề 3D, thân khóa đa điểm đồng bộ Draho | C41: CDMQ-50.12 | D41: ='[1]CDMQ-50.12'!C6 -> 2.6 | E41: ='[1]CDMQ-50.12'!C7 -> 2.2 | F41: m2 | G41: ='[1]CDMQ-50.12'!F7 -> 100 | H41: =D41*E41*G41 -> 572 | I41: ='[1]CDMQ-50.12'!F4 -> 3215000 | J41: =H41*I41 -> 1.83898e+09
A42: =IFERROR(A41*1,0)+1 -> 23 | B42: ='[1]CDMQ-50.13'!G3&CHAR(10)&'[1]CDMQ-50.13'!G4&CHAR(10)&'[1]CDMQ-50.13'!G5&CHAR(10)&'[1]CDMQ-50.13'!G6 -> Cửa đi mở quay 2 cánh + ô kính cố định - Nhôm hệ Nova 50 - Kính trắng cường lực dày 10mm - Phụ kiện bản lề 3D, thân khóa đa điểm đồng bộ Draho | C42: CDMQ-50.13 | D42: ='[1]CDMQ-50.13'!C6 -> 2.6 | E42: ='[1]CDMQ-50.13'!C7 -> 2.7 | F42: m2 | G42: ='[1]CDMQ-50.13'!F7 -> 100 | H42: =D42*E42*G42 -> 702 | I42: ='[1]CDMQ-50.13'!F4 -> 3070000 | J42: =H42*I42 -> 2155140000
A43: =IFERROR(A42*1,0)+1 -> 24 | B43: ='[1]CDMQ-50.14'!G3&CHAR(10)&'[1]CDMQ-50.14'!G4&CHAR(10)&'[1]CDMQ-50.14'!G5&CHAR(10)&'[1]CDMQ-50.14'!G6 -> Cửa đi mở quay 4 cánh - Nhôm hệ Nova 50 - Kính trắng cường lực dày 10mm - Phụ kiện bản lề 3D, thân khóa đa điểm đồng bộ Draho | C43: CDMQ-50.14 | D43: ='[1]CDMQ-50.14'!C6 -> 2.4 | E43: ='[1]CDMQ-50.14'!C7 -> 2.2 | F43: m2 | G43: ='[1]CDMQ-50.14'!F7 -> 100 | H43: =D43*E43*G43 -> 528 | I43: ='[1]CDMQ-50.14'!F4 -> 3835000 | J43: =H43*I43 -> 2024880000
...

Sheet CSL-50.01
A1: Phụ kiện | B1: Loại cửa | C1: Kính | E1: ="Nhôm: "&ROUND(I13/I188*100,0)&"%" -> Nhôm: 47% | F1: ="Kính: "&ROUND(I112/I188*100,0)&"%" -> Kính: 9% | G1: ="Vật tư phụ: "&100-(ROUND(I13/I188*100,0)+ROUND(I112/I188*100,0)+ROUND((I126+I186)/I188*100,0))&"%" -> Vật tư phụ: 22% | H1: ="Nhân công: "&ROUND((I126+I186)/I188*100,0)&"%" -> Nhân công: 22%
A2: =pkcn50.65 -> Draho | B2: CỬA SỔ LÙA | C2: k8cl | E2: =I13/I188*F4 -> 1929576 | F2: =I112/I188*F4 -> 349557.63 | G2: =F4-(E2+F2+H2) -> 920699.67 | H2: =(I126+I186)/I188*F4 -> 903166.71
A3: CSL50-2C | E3: Tên cửa: | F3: CSL-50.01 | G3: Cửa sổ lùa 2 cánh
E4: Đ.Giá (VND/m2): | F4: =ROUNDUP(F6/F5,-3) -> 4103000 | G4: - Nhôm hệ Nova 50
E5: Diện tích (m2): | F5: =C6*C7 -> 0.72 | G5: ="- "&INDEX(tenkinh,MATCH(C2,makinh,0),0) -> - Kính trắng cường lực dày 8mm
A6: Kích thước | B6: W | C6: 1.2 | E6: Tổng giá (VND): | F6: =I188/(1-bctc-cpcty-dpp-dpbh-cpk) -> 2953565.9 | G6: =INDEX(ghichuvattu,MATCH($A$3,mavattu,0)) -> - Phụ kiện bánh xe đôi, khóa âm đồng bộ Draho
B7: H | C7: 0.6 | E7: Số bộ: | F7: =SUMIF(MACUA,F3,SOLUONG) -> 100
B8: W1 | E8: % Kính: | F8: =G121/F5/2 -> 0.62658333
B9: H1
B10: W2
B11: H2
A12: Diễn giải vật tư | B12: Mã vật tư | C12: Công thức | D12: Chiều dài (m) | E12: Số lượng | F12: KL (kg/m) | G12: S KL (kg) | H12: Đơn giá (Chưa VAT) | I12: Tổng giá
A13: A. GIÁ VẬT TƯ NHÔM | G13: =SUBTOTAL(9,G14:G71) -> 8.1808534 | I13: =SUBTOTAL(9,I14:I71) -> 930640.26
A14: =IFERROR(INDEX(TENPROFILE,MATCH(B14,MAPROFILE,0)),"") -> Khung bao sổ lùa | B14: WSAW-5010 | C14: H | D14: =INDEX($B$4:$C$11,MATCH(C14,$B$4:$B$11,0),2)-J14 -> 0.59 | E14: 2 | F14: =IFERROR(VLOOKUP(B14,Alu_data,2,0),"") -> 0.901 | G14: =(1+hp_nhom)*D14*E14*F14 -> 1.1269708 | H14: =gn_csl -> 116300 | I14: =G14*H14 -> 131066.7 | J14: =0.005*2 -> 0.01
A15: =IFERROR(INDEX(TENPROFILE,MATCH(B15,MAPROFILE,0)),"") -> Khung bao sổ lùa | B15: WSAW-5010 | C15: W | D15: =INDEX($B$4:$C$11,MATCH(C15,$B$4:$B$11,0),2)-J15 -> 1.19 | E15: 2 | F15: =IFERROR(VLOOKUP(B15,Alu_data,2,0),"") -> 0.901 | G15: =(1+hp_nhom)*D15*E15*F15 -> 2.2730428 | H15: =gn_csl -> 116300 | I15: =G15*H15 -> 264354.88 | J15: =0.005*2 -> 0.01
A16: =IFERROR(INDEX(TENPROFILE,MATCH(B16,MAPROFILE,0)),"") -> Thanh ray | B16: WSAW-5014 | C16: W | D16: =INDEX($B$4:$C$11,MATCH(C16,$B$4:$B$11,0),2)-J16 -> 1.116 | E16: 2 | F16: =IFERROR(VLOOKUP(B16,Alu_data,2,0),"") -> 0.093 | G16: =(1+hp_nhom)*D16*E16*F16 -> 0.22003056 | H16: =gn_csl -> 116300 | I16: =G16*H16 -> 25589.554 | J16: =0.042*2 -> 0.084
A18: =IFERROR(INDEX(TENPROFILE,MATCH(B18,MAPROFILE,0)),"") -> Khung cánh sổ lùa | B18: WSAW-5011 | C18: H | D18: =INDEX($B$4:$C$11,MATCH(C18,$B$4:$B$11,0),2)-J18 -> 0.532 | E18: 4 | F18: =IFERROR(VLOOKUP(B18,Alu_data,2,0),"") -> 0.676 | G18: =(1+hp_nhom)*D18*E18*F18 -> 1.5248397 | H18: =gn_csl -> 116300 | I18: =G18*H18 -> 177338.85 | J18: =0.034*2 -> 0.068
A19: =IFERROR(INDEX(TENPROFILE,MATCH(B19,MAPROFILE,0)),"") -> Thanh khóa cánh | B19: WSAW-5013 | C19: H | D19: =INDEX($B$4:$C$11,MATCH(C19,$B$4:$B$11,0),2)-J19 -> 0.532 | F19: =IFERROR(VLOOKUP(B19,Alu_data,2,0),"") -> 0.268 | G19: =(1+hp_nhom)*D19*E19*F19 -> 0 | H19: =gn_csl -> 116300 | I19: =G19*H19 -> 0 | J19: =J18 -> 0.068
A20: =IFERROR(INDEX(TENPROFILE,MATCH(B20,MAPROFILE,0)),"") -> Thanh móc sổ lùa | B20: WSAW-5012 | C20: H | D20: =INDEX($B$4:$C$11,MATCH(C20,$B$4:$B$11,0),2)-J20 -> 0.532 | E20: =E18/2 -> 2 | F20: =IFERROR(VLOOKUP(B20,Alu_data,2,0),"") -> 0.246 | G20: =(1+hp_nhom)*D20*E20*F20 -> 0.27744864 | H20: =gn_csl -> 116300 | I20: =G20*H20 -> 32267.277 | J20: =J18 -> 0.068
A21: =IFERROR(INDEX(TENPROFILE,MATCH(B21,MAPROFILE,0)),"") -> Khung cánh sổ lùa | B21: WSAW-5011 | C21: W | D21: =INDEX($B$4:$C$11,MATCH(C21,$B$4:$B$11,0),2)-J21 -> 1.132 | E21: 2 | F21: =IFERROR(VLOOKUP(B21,Alu_data,2,0),"") -> 0.676 | G21: =(1+hp_nhom)*D21*E21*F21 -> 1.6222918 | H21: =gn_csl -> 116300 | I21: =G21*H21 -> 188672.54 | J21: =0.034*2 -> 0.068
A23: =IFERROR(INDEX(TENPROFILE,MATCH(B23,MAPROFILE,0)),"") -> Ke góc | B23: ALWS-BK007-1 | D23: 0.05 | E23: 4 | F23: =IFERROR(VLOOKUP(B23,Alu_data,2,0),"") -> 1.231571 | G23: =(1+hp_nhom)*D23*E23*F23 -> 0.26109306 | H23: =gnt -> 98000 | I23: =G23*H23 -> 25587.12
A24: =IFERROR(INDEX(TENPROFILE,MATCH(B24,MAPROFILE,0)),"") -> Ke khung cánh (hệ XingFa) | B24: XF01687 | D24: 0.05 | E24: =4*E18/2 -> 8 | F24: =IFERROR(VLOOKUP(B24,Alu_data,2,0),"") -> 2.064 | G24: =(1+hp_nhom)*D24*E24*F24 -> 0.875136 | H24: =gnt -> 98000 | I24: =G24*H24 -> 85763.328
A72: B. GIÁ VẬT TƯ PHỤ | B72: Mã quy đổi | C72: Đơn vị | D72: Mã BM | I72: =SUBTOTAL(9,I73:I111) -> 116100
A73: =_xlfn.IFNA(INDEX(diengiaivattu,MATCH(B73,mavattu,0),0),0) -> Bơm Foam | B73: foam | C73: =_xlfn.IFNA(INDEX(donvivattu,MATCH(B73,mavattu,0),0),0) -> Mét | E73: =(C6+C7)*2 -> 3.6 | G73: =E73 -> 3.6 | H73: =_xlfn.IFNA(INDEX(dongiavattu,MATCH(B73,mavattu,0),0),0) -> 20000 | I73: =G73*H73 -> 72000
A74: =_xlfn.IFNA(INDEX(diengiaivattu,MATCH(B74,mavattu,0),0),0) -> Ốc vít | B74: OcVit | C74: =_xlfn.IFNA(INDEX(donvivattu,MATCH(B74,mavattu,0),0),0) -> Cái | E74: =15+E23*4+E24*4+ROUNDUP(D19/0.5,0)*E19 -> 63 | G74: =E74*(1+hp_vtk) -> 66.15 | H74: =_xlfn.IFNA(INDEX(dongiavattu,MATCH(B74,mavattu,0),0),0) -> 600 | I74: =G74*H74 -> 39690
A75: =_xlfn.IFNA(INDEX(diengiaivattu,MATCH(B75,mavattu,0),0),0) -> Nút bịt nhựa | B75: NutBN | C75: =_xlfn.IFNA(INDEX(donvivattu,MATCH(B75,mavattu,0),0),0) -> Cái | E75: =ROUNDUP(C6/0.5,0)*2 -> 6 | G75: =E75*(1+hp_vtk) -> 6.3 | H75: =_xlfn.IFNA(INDEX(dongiavattu,MATCH(B75,mavattu,0),0),0) -> 700 | I75: =G75*H75 -> 4410
A76: =_xlfn.IFNA(INDEX(diengiaivattu,MATCH(B76,mavattu,0),0),0) -> 0
A112: C. GIÁ VẬT TƯ KÍNH | C112: W (m) | D112: H (m) | E112: Tổng diện tích (m2) | F112: Số lượng (tấm) | G112: Ʃ dự trù (m2) | I112: =SUBTOTAL(9,I113:I125) -> 168592.69
A113: =_xlfn.IFNA(INDEX( tenkinh,MATCH(B113,makinh,0),0),"") -> Kính trắng cường lực dày 8mm | B113: =C2 -> k8cl | C113: =(C6-J113)/F113 -> 0.5 | D113: =C7-K113 -> 0.438 | E113: =D113*C113 -> 0.219 | F113: 2 | G113: =E113*F113*(1+hp_kinh) -> 0.45114 | H113: =_xlfn.IFNA(INDEX(dongiakinh,MATCH(B113,makinh,0),0),0) -> 353703.7 | I113: =G113*H113 -> 159569.89 | J113: =0.081*2+0.038 -> 0.2 | K113: =0.081*2 -> 0.162
A117: =_xlfn.IFNA(INDEX(tenkinh,MATCH(B117,makinh,0),0),0) -> 0
A118: =_xlfn.IFNA(INDEX(tenkinh,MATCH(B118,makinh,0),0),0) -> 0
A119: =_xlfn.IFNA(INDEX(tenkinh,MATCH(B119,makinh,0),0),0) -> 0
A120: =_xlfn.IFNA(INDEX(tenkinh,MATCH(B120,makinh,0),0),0) -> 0
A121: =_xlfn.IFNA(INDEX(tenkinh,MATCH(B121,makinh,0),0),0) -> Băng keo bảo vệ kính | B121: bk | G121: =SUM(G113:G120)*2 -> 0.90228 | H121: =_xlfn.IFNA(INDEX(dongiakinh,MATCH(B121,makinh,0),0),0) -> 10000 | I121: =G121*H121 -> 9022.8
A122: =_xlfn.IFNA(INDEX(tenkinh,MATCH(B122,makinh,0),0),0) -> Mài thô | B122: mai | G122: =G121/2 -> 0.45114 | H122: =_xlfn.IFNA(INDEX(dongiakinh,MATCH(B122,makinh,0),0),0) -> 0 | I122: =G122*H122 -> 0
A123: =_xlfn.IFNA(INDEX(tenkinh,MATCH(B123,makinh,0),0),0) -> Mài bóng | B123: maibong | G123: =F123*(1+hp_kinh) -> 0 | H123: =_xlfn.IFNA(INDEX(dongiakinh,MATCH(B123,makinh,0),0),0) -> 8000 | I123: =G123*H123 -> 0
A124: =_xlfn.IFNA(INDEX(tenkinh,MATCH(B124,makinh,0),0),0) -> Khoét lỗ | B124: khoet | G124: =F124*(1+hp_kinh) -> 0 | H124: =_xlfn.IFNA(INDEX(dongiakinh,MATCH(B124,makinh,0),0),0) -> 20000 | I124: =G124*H124 -> 0
A125: =_xlfn.IFNA(INDEX(tenkinh,MATCH(B125,makinh,0),0),0) -> Khoan lỗ | B125: khoanlo | G125: =F125*(1+hp_kinh) -> 0 | H125: =_xlfn.IFNA(INDEX(dongiakinh,MATCH(B125,makinh,0),0),0) -> 5000 | I125: =G125*H125 -> 0
A126: D. CHI PHÍ SẢN XUẤT | I126: =SUBTOTAL(9,I127:I135) -> 363600
A127: ="D.1 NHÂN CÔNG GIA CÔNG ("&B2&")" -> D.1 NHÂN CÔNG GIA CÔNG (CỬA SỔ LÙA) | G127: =$F$5 -> 0.72 | H127: =ncsx_csl -> 175000 | I127: =G127*H127 -> 126000
...

Sheet CSL-50.02
A1: Phụ kiện | B1: Loại cửa | C1: Kính | E1: ="Nhôm: "&ROUND(I13/I188*100,0)&"%" -> Nhôm: 45% | F1: ="Kính: "&ROUND(I112/I188*100,0)&"%" -> Kính: 12% | G1: ="Vật tư phụ: "&100-(ROUND(I13/I188*100,0)+ROUND(I112/I188*100,0)+ROUND((I126+I186)/I188*100,0))&"%" -> Vật tư phụ: 17% | H1: ="Nhân công: "&ROUND((I126+I186)/I188*100,0)&"%" -> Nhân công: 26%
A2: =pkcn50.65 -> Draho | B2: CỬA SỔ LÙA | C2: k8cl | E2: =I13/I188*F4 -> 1525398.4 | F2: =I112/I188*F4 -> 408179.59 | G2: =F4-(E2+F2+H2) -> 572272.87 | H2: =(I126+I186)/I188*F4 -> 903149.11
A3: CSL50-2C | C3: k8cl | E3: Tên cửa: | F3: CSL-50.02 | G3: Cửa sổ lùa 2 cánh + ô kính cố định
E4: Đ.Giá (VND/m2): | F4: =ROUNDUP(F6/F5,-3) -> 3409000 | G4: - Nhôm hệ Nova 50
E5: Diện tích (m2): | F5: =C6*C7 -> 1.32 | G5: ="- "&INDEX(tenkinh,MATCH(C2,makinh,0),0) -> - Kính trắng cường lực dày 8mm
A6: Kích thước | B6: W | C6: 1.2 | E6: Tổng giá (VND): | F6: =I188/(1-bctc-cpcty-dpp-dpbh-cpk) -> 4499062.7 | G6: =INDEX(ghichuvattu,MATCH($A$3,mavattu,0)) -> - Phụ kiện bánh xe đôi, khóa âm đồng bộ Draho
B7: H | C7: 1.1 | E7: Số bộ: | F7: =SUMIF(MACUA,F3,SOLUONG) -> 100
B8: W1 | C8: =C6 -> 1.2 | D8: Cửa | E8: % Kính: | F8: =G121/F5/2 -> 0.73167767
B9: H1 | C9: 0.6 | D9: Cửa
B10: W2 | C10: =C6 -> 1.2 | D10: Fix
B11: H2 | C11: =C7-C9 -> 0.5 | D11: Fix
A12: Diễn giải vật tư | B12: Mã vật tư | C12: Công thức | D12: Chiều dài (m) | E12: Số lượng | F12: KL (kg/m) | G12: S KL (kg) | H12: Đơn giá (Chưa VAT) | I12: Tổng giá
A13: A. GIÁ VẬT TƯ NHÔM | G13: =SUBTOTAL(9,G14:G71) -> 11.859492 | I13: =SUBTOTAL(9,I14:I71) -> 1348817.3
A14: =IFERROR(INDEX(TENPROFILE,MATCH(B14,MAPROFILE,0)),"") -> Khung bao sổ lùa | B14: WSAW-5010 | C14: H1 | D14: =INDEX($B$4:$C$11,MATCH(C14,$B$4:$B$11,0),2)-J14 -> 0.595 | E14: 2 | F14: =IFERROR(VLOOKUP(B14,Alu_data,2,0),"") -> 0.901 | G14: =(1+hp_nhom)*D14*E14*F14 -> 1.1365214 | H14: =gn_csl -> 116300 | I14: =G14*H14 -> 132177.44 | J14: =0.005 -> 0.005
A15: =IFERROR(INDEX(TENPROFILE,MATCH(B15,MAPROFILE,0)),"") -> Khung bao sổ lùa | B15: WSAW-5010 | C15: W1 | D15: =INDEX($B$4:$C$11,MATCH(C15,$B$4:$B$11,0),2)-J15 -> 1.19 | E15: 2 | F15: =IFERROR(VLOOKUP(B15,Alu_data,2,0),"") -> 0.901 | G15: =(1+hp_nhom)*D15*E15*F15 -> 2.2730428 | H15: =gn_csl -> 116300 | I15: =G15*H15 -> 264354.88 | J15: =0.005*2 -> 0.01
A16: =IFERROR(INDEX(TENPROFILE,MATCH(B16,MAPROFILE,0)),"") -> Thanh ray | B16: WSAW-5014 | C16: W1 | D16: =INDEX($B$4:$C$11,MATCH(C16,$B$4:$B$11,0),2)-J16 -> 1.116 | E16: 2 | F16: =IFERROR(VLOOKUP(B16,Alu_data,2,0),"") -> 0.093 | G16: =(1+hp_nhom)*D16*E16*F16 -> 0.22003056 | H16: =gn_csl -> 116300 | I16: =G16*H16 -> 25589.554 | J16: =0.042*2 -> 0.084
A18: =IFERROR(INDEX(TENPROFILE,MATCH(B18,MAPROFILE,0)),"") -> Khung cánh sổ lùa | B18: WSAW-5011 | C18: H1 | D18: =INDEX($B$4:$C$11,MATCH(C18,$B$4:$B$11,0),2)-J18 -> 0.537 | E18: 4 | F18: =IFERROR(VLOOKUP(B18,Alu_data,2,0),"") -> 0.676 | G18: =(1+hp_nhom)*D18*E18*F18 -> 1.5391709 | H18: =gn_csl -> 116300 | I18: =G18*H18 -> 179005.57 | J18: =0.034+0.029 -> 0.063
A19: =IFERROR(INDEX(TENPROFILE,MATCH(B19,MAPROFILE,0)),"") -> Thanh khóa cánh | B19: WSAW-5013 | C19: H1 | D19: =INDEX($B$4:$C$11,MATCH(C19,$B$4:$B$11,0),2)-J19 -> 0.537 | F19: =IFERROR(VLOOKUP(B19,Alu_data,2,0),"") -> 0.268 | G19: =(1+hp_nhom)*D19*E19*F19 -> 0 | H19: =gn_csl -> 116300 | I19: =G19*H19 -> 0 | J19: =J18 -> 0.063
A20: =IFERROR(INDEX(TENPROFILE,MATCH(B20,MAPROFILE,0)),"") -> Thanh móc sổ lùa | B20: WSAW-5012 | C20: H1 | D20: =INDEX($B$4:$C$11,MATCH(C20,$B$4:$B$11,0),2)-J20 -> 0.537 | E20: =E18/2 -> 2 | F20: =IFERROR(VLOOKUP(B20,Alu_data,2,0),"") -> 0.246 | G20: =(1+hp_nhom)*D20*E20*F20 -> 0.28005624 | H20: =gn_csl -> 116300 | I20: =G20*H20 -> 32570.541 | J20: =J18 -> 0.063
A21: =IFERROR(INDEX(TENPROFILE,MATCH(B21,MAPROFILE,0)),"") -> Khung cánh sổ lùa | B21: WSAW-5011 | C21: W1 | D21: =INDEX($B$4:$C$11,MATCH(C21,$B$4:$B$11,0),2)-J21 -> 1.132 | E21: 2 | F21: =IFERROR(VLOOKUP(B21,Alu_data,2,0),"") -> 0.676 | G21: =(1+hp_nhom)*D21*E21*F21 -> 1.6222918 | H21: =gn_csl -> 116300 | I21: =G21*H21 -> 188672.54 | J21: =0.034*2 -> 0.068
A23: =IFERROR(INDEX(TENPROFILE,MATCH(B23,MAPROFILE,0)),"") -> Ke góc | B23: ALWS-BK007-1 | D23: 0.05 | E23: 4 | F23: =IFERROR(VLOOKUP(B23,Alu_data,2,0),"") -> 1.231571 | G23: =(1+hp_nhom)*D23*E23*F23 -> 0.26109306 | H23: =gnt -> 98000 | I23: =G23*H23 -> 25587.12
A24: =IFERROR(INDEX(TENPROFILE,MATCH(B24,MAPROFILE,0)),"") -> Ke khung cánh (hệ XingFa) | B24: XF01687 | D24: 0.05 | E24: =4*E18/2 -> 8 | F24: =IFERROR(VLOOKUP(B24,Alu_data,2,0),"") -> 2.064 | G24: =(1+hp_nhom)*D24*E24*F24 -> 0.875136 | H24: =gnt -> 98000 | I24: =G24*H24 -> 85763.328
A26: =IFERROR(INDEX(TENPROFILE,MATCH(B26,MAPROFILE,0)),"") -> Thanh nối khung | B26: WSAW-5009 | C26: W | D26: =INDEX($B$4:$C$11,MATCH(C26,$B$4:$B$11,0),2)-J26 -> 1.19 | E26: 1 | F26: =IFERROR(VLOOKUP(B26,Alu_data,2,0),"") -> 0.211 | G26: =(1+hp_nhom)*D26*E26*F26 -> 0.2661554 | H26: =gnt -> 98000 | I26: =G26*H26 -> 26083.229 | J26: =0.005*2 -> 0.01 | K26: Chia khung
A28: =IFERROR(INDEX(TENPROFILE,MATCH(B28,MAPROFILE,0)),"") -> Khung bao cố định | B28: WSAW-5001 | C28: H2 | D28: =INDEX($B$4:$C$11,MATCH(C28,$B$4:$B$11,0),2)-J28 -> 0.495 | E28: 2 | F28: =IFERROR(VLOOKUP(B28,Alu_data,2,0),"") -> 0.661 | G28: =(1+hp_nhom)*D28*E28*F28 -> 0.6936534 | H28: =gn_csl -> 116300 | I28: =G28*H28 -> 80671.89 | J28: 0.005 | K28: Fix
A29: =IFERROR(INDEX(TENPROFILE,MATCH(B29,MAPROFILE,0)),"") -> Khung bao cố định | B29: WSAW-5001 | C29: W2 | D29: =INDEX($B$4:$C$11,MATCH(C29,$B$4:$B$11,0),2)-J29 -> 1.19 | E29: 2 | F29: =IFERROR(VLOOKUP(B29,Alu_data,2,0),"") -> 0.661 | G29: =(1+hp_nhom)*D29*E29*F29 -> 1.6675708 | H29: =gn_csl -> 116300 | I29: =G29*H29 -> 193938.48 | J29: =0.005*2 -> 0.01
A30: =IFERROR(INDEX(TENPROFILE,MATCH(B30,MAPROFILE,0)),"") -> Nẹp kính | B30: WSAW-5007 | C30: H2 | D30: =INDEX($B$4:$C$11,MATCH(C30,$B$4:$B$11,0),2)-J30 -> 0.453 | E30: =E28 -> 2 | F30: =IFERROR(VLOOKUP(B30,Alu_data,2,0),"") -> 0.225 | G30: =(1+hp_nhom)*D30*E30*F30 -> 0.216081 | H30: =gn_csl -> 116300 | I30: =G30*H30 -> 25130.22 | J30: =0.026+0.021 -> 0.047
A31: =IFERROR(INDEX(TENPROFILE,MATCH(B31,MAPROFILE,0)),"") -> Nẹp kính | B31: WSAW-5007 | C31: W2 | D31: =INDEX($B$4:$C$11,MATCH(C31,$B$4:$B$11,0),2)-J31 -> 1.148 | E31: =E29 -> 2 | F31: =IFERROR(VLOOKUP(B31,Alu_data,2,0),"") -> 0.225 | G31: =(1+hp_nhom)*D31*E31*F31 -> 0.547596 | H31: =gn_csl -> 116300 | I31: =G31*H31 -> 63685.415 | J31: =0.026*2 -> 0.052
A33: =IFERROR(INDEX(TENPROFILE,MATCH(B33,MAPROFILE,0)),"") -> Ke góc | B33: ALWS-BK007-1 | D33: 0.05 | E33: 4 | F33: =IFERROR(VLOOKUP(B33,Alu_data,2,0),"") -> 1.231571 | G33: =(1+hp_nhom)*D33*E33*F33 -> 0.26109306 | H33: =gnt -> 98000 | I33: =G33*H33 -> 25587.12
A72: B. GIÁ VẬT TƯ PHỤ | B72: Mã quy đổi | C72: Đơn vị | D72: Mã BM | I72: =SUBTOTAL(9,I73:I111) -> 148070
A73: =_xlfn.IFNA(INDEX(diengiaivattu,MATCH(B73,mavattu,0),0),0) -> Bơm Foam | B73: foam | C73: =_xlfn.IFNA(INDEX(donvivattu,MATCH(B73,mavattu,0),0),0) -> Mét | E73: =(C6+C7)*2 -> 4.6 | G73: =E73 -> 4.6 | H73: =_xlfn.IFNA(INDEX(dongiavattu,MATCH(B73,mavattu,0),0),0) -> 20000 | I73: =G73*H73 -> 92000
A74: =_xlfn.IFNA(INDEX(diengiaivattu,MATCH(B74,mavattu,0),0),0) -> Ốc vít | B74: OcVit | C74: =_xlfn.IFNA(INDEX(donvivattu,MATCH(B74,mavattu,0),0),0) -> Cái | E74: =15+E23*4+E24*4+ROUNDUP(D19/0.5,0)*E19+ROUNDUP(D26/0.5,0)*E26+E33*4 -> 82 | G74: =E74*(1+hp_vtk) -> 86.1 | H74: =_xlfn.IFNA(INDEX(dongiavattu,MATCH(B74,mavattu,0),0),0) -> 600 | I74: =G74*H74 -> 51660
A75: =_xlfn.IFNA(INDEX(diengiaivattu,MATCH(B75,mavattu,0),0),0) -> Nút bịt nhựa | B75: NutBN | C75: =_xlfn.IFNA(INDEX(donvivattu,MATCH(B75,mavattu,0),0),0) -> Cái | E75: =ROUNDUP(C6/0.5,0)*2 -> 6 | G75: =E75*(1+hp_vtk) -> 6.3 | H75: =_xlfn.IFNA(INDEX(dongiavattu,MATCH(B75,mavattu,0),0),0) -> 700 | I75: =G75*H75 -> 4410
A112: C. GIÁ VẬT TƯ KÍNH | C112: W (m) | D112: H (m) | E112: Tổng diện tích (m2) | F112: Số lượng (tấm) | G112: Ʃ dự trù (m2) | I112: =SUBTOTAL(9,I113:I125) -> 360928.46
A113: =_xlfn.IFNA(INDEX( tenkinh,MATCH(B113,makinh,0),0),"") -> Kính trắng cường lực dày 8mm | B113: =C2 -> k8cl | C113: =(C8-J113)/F113 -> 0.5 | D113: =C9-K113 -> 0.443 | E113: =D113*C113 -> 0.2215 | F113: 2 | G113: =E113*F113*(1+hp_kinh) -> 0.45629 | H113: =_xlfn.IFNA(INDEX(dongiakinh,MATCH(B113,makinh,0),0),0) -> 353703.7 | I113: =G113*H113 -> 161391.46 | J113: =0.081*2+0.038 -> 0.2 | K113: =0.081+0.076 -> 0.157 | L113: =D8 -> Cửa
A114: =_xlfn.IFNA(INDEX( tenkinh,MATCH(B114,makinh,0),0),"") -> Kính trắng cường lực dày 8mm | B114: =C3 -> k8cl | C114: =(C10-J114)/F114 -> 1.132 | D114: =C11-K114 -> 0.437 | E114: =D114*C114 -> 0.494684 | F114: 1 | G114: =E114*F114*(1+hp_kinh) -> 0.50952452 | H114: =_xlfn.IFNA(INDEX(dongiakinh,MATCH(B114,makinh,0),0),0) -> 353703.7 | I114: =G114*H114 -> 180220.71 | J114: =0.034*2 -> 0.068 | K114: =0.034+0.029 -> 0.063 | L114: =D10 -> Fix
A117: =_xlfn.IFNA(INDEX(tenkinh,MATCH(B117,makinh,0),0),0) -> 0
A118: =_xlfn.IFNA(INDEX(tenkinh,MATCH(B118,makinh,0),0),0) -> 0
A119: =_xlfn.IFNA(INDEX(tenkinh,MATCH(B119,makinh,0),0),0) -> 0
A120: =_xlfn.IFNA(INDEX(tenkinh,MATCH(B120,makinh,0),0),0) -> 0
A121: =_xlfn.IFNA(INDEX(tenkinh,MATCH(B121,makinh,0),0),0) -> Băng keo bảo vệ kính | B121: bk | G121: =SUM(G113:G120)*2 -> 1.931629 | H121: =_xlfn.IFNA(INDEX(dongiakinh,MATCH(B121,makinh,0),0),0) -> 10000 | I121: =G121*H121 -> 19316.29
...

Sheet CSL-50.03
A1: Phụ kiện | B1: Loại cửa | C1: Kính | E1: ="Nhôm: "&ROUND(I13/I188*100,0)&"%" -> Nhôm: 45% | F1: ="Kính: "&ROUND(I112/I188*100,0)&"%" -> Kính: 12% | G1: ="Vật tư phụ: "&100-(ROUND(I13/I188*100,0)+ROUND(I112/I188*100,0)+ROUND((I126+I186)/I188*100,0))&"%" -> Vật tư phụ: 17% | H1: ="Nhân công: "&ROUND((I126+I186)/I188*100,0)&"%" -> Nhân công: 26%
A2: =pkcn50.65 -> Draho | B2: CỬA SỔ LÙA | C2: k8cl | E2: =I13/I188*F4 -> 1525398.4 | F2: =I112/I188*F4 -> 408179.59 | G2: =F4-(E2+F2+H2) -> 572272.87 | H2: =(I126+I186)/I188*F4 -> 903149.11
A3: CSL50-2C | C3: k8cl | E3: Tên cửa: | F3: CSL-50.03 | G3: Cửa sổ lùa 2 cánh + ô kính cố định
E4: Đ.Giá (VND/m2): | F4: =ROUNDUP(F6/F5,-3) -> 3409000 | G4: - Nhôm hệ Nova 50
E5: Diện tích (m2): | F5: =C6*C7 -> 1.32 | G5: ="- "&INDEX(tenkinh,MATCH(C2,makinh,0),0) -> - Kính trắng cường lực dày 8mm
A6: Kích thước | B6: W | C6: 1.2 | E6: Tổng giá (VND): | F6: =I188/(1-bctc-cpcty-dpp-dpbh-cpk) -> 4499062.7 | G6: =INDEX(ghichuvattu,MATCH($A$3,mavattu,0)) -> - Phụ kiện bánh xe đôi, khóa âm đồng bộ Draho
B7: H | C7: 1.1 | E7: Số bộ: | F7: =SUMIF(MACUA,F3,SOLUONG) -> 100
B8: W1 | C8: =C6 -> 1.2 | D8: Cửa | E8: % Kính: | F8: =G121/F5/2 -> 0.73167767
B9: H1 | C9: 0.6 | D9: Cửa
B10: W2 | C10: =C6 -> 1.2 | D10: Fix
B11: H2 | C11: =C7-C9 -> 0.5 | D11: Fix
A12: Diễn giải vật tư | B12: Mã vật tư | C12: Công thức | D12: Chiều dài (m) | E12: Số lượng | F12: KL (kg/m) | G12: S KL (kg) | H12: Đơn giá (Chưa VAT) | I12: Tổng giá
A13: A. GIÁ VẬT TƯ NHÔM | G13: =SUBTOTAL(9,G14:G71) -> 11.859492 | I13: =SUBTOTAL(9,I14:I71) -> 1348817.3
A14: =IFERROR(INDEX(TENPROFILE,MATCH(B14,MAPROFILE,0)),"") -> Khung bao sổ lùa | B14: WSAW-5010 | C14: H1 | D14: =INDEX($B$4:$C$11,MATCH(C14,$B$4:$B$11,0),2)-J14 -> 0.595 | E14: 2 | F14: =IFERROR(VLOOKUP(B14,Alu_data,2,0),"") -> 0.901 | G14: =(1+hp_nhom)*D14*E14*F14 -> 1.1365214 | H14: =gn_csl -> 116300 | I14: =G14*H14 -> 132177.44 | J14: =0.005 -> 0.005
A15: =IFERROR(INDEX(TENPROFILE,MATCH(B15,MAPROFILE,0)),"") -> Khung bao sổ lùa | B15: WSAW-5010 | C15: W1 | D15: =INDEX($B$4:$C$11,MATCH(C15,$B$4:$B$11,0),2)-J15 -> 1.19 | E15: 2 | F15: =IFERROR(VLOOKUP(B15,Alu_data,2,0),"") -> 0.901 | G15: =(1+hp_nhom)*D15*E15*F15 -> 2.2730428 | H15: =gn_csl -> 116300 | I15: =G15*H15 -> 264354.88 | J15: =0.005*2 -> 0.01
A16: =IFERROR(INDEX(TENPROFILE,MATCH(B16,MAPROFILE,0)),"") -> Thanh ray | B16: WSAW-5014 | C16: W1 | D16: =INDEX($B$4:$C$11,MATCH(C16,$B$4:$B$11,0),2)-J16 -> 1.116 | E16: 2 | F16: =IFERROR(VLOOKUP(B16,Alu_data,2,0),"") -> 0.093 | G16: =(1+hp_nhom)*D16*E16*F16 -> 0.22003056 | H16: =gn_csl -> 116300 | I16: =G16*H16 -> 25589.554 | J16: =0.042*2 -> 0.084
A18: =IFERROR(INDEX(TENPROFILE,MATCH(B18,MAPROFILE,0)),"") -> Khung cánh sổ lùa | B18: WSAW-5011 | C18: H1 | D18: =INDEX($B$4:$C$11,MATCH(C18,$B$4:$B$11,0),2)-J18 -> 0.537 | E18: 4 | F18: =IFERROR(VLOOKUP(B18,Alu_data,2,0),"") -> 0.676 | G18: =(1+hp_nhom)*D18*E18*F18 -> 1.5391709 | H18: =gn_csl -> 116300 | I18: =G18*H18 -> 179005.57 | J18: =0.034+0.029 -> 0.063
A19: =IFERROR(INDEX(TENPROFILE,MATCH(B19,MAPROFILE,0)),"") -> Thanh khóa cánh | B19: WSAW-5013 | C19: H1 | D19: =INDEX($B$4:$C$11,MATCH(C19,$B$4:$B$11,0),2)-J19 -> 0.537 | F19: =IFERROR(VLOOKUP(B19,Alu_data,2,0),"") -> 0.268 | G19: =(1+hp_nhom)*D19*E19*F19 -> 0 | H19: =gn_csl -> 116300 | I19: =G19*H19 -> 0 | J19: =J18 -> 0.063
A20: =IFERROR(INDEX(TENPROFILE,MATCH(B20,MAPROFILE,0)),"") -> Thanh móc sổ lùa | B20: WSAW-5012 | C20: H1 | D20: =INDEX($B$4:$C$11,MATCH(C20,$B$4:$B$11,0),2)-J20 -> 0.537 | E20: =E18/2 -> 2 | F20: =IFERROR(VLOOKUP(B20,Alu_data,2,0),"") -> 0.246 | G20: =(1+hp_nhom)*D20*E20*F20 -> 0.28005624 | H20: =gn_csl -> 116300 | I20: =G20*H20 -> 32570.541 | J20: =J18 -> 0.063
A21: =IFERROR(INDEX(TENPROFILE,MATCH(B21,MAPROFILE,0)),"") -> Khung cánh sổ lùa | B21: WSAW-5011 | C21: W1 | D21: =INDEX($B$4:$C$11,MATCH(C21,$B$4:$B$11,0),2)-J21 -> 1.132 | E21: 2 | F21: =IFERROR(VLOOKUP(B21,Alu_data,2,0),"") -> 0.676 | G21: =(1+hp_nhom)*D21*E21*F21 -> 1.6222918 | H21: =gn_csl -> 116300 | I21: =G21*H21 -> 188672.54 | J21: =0.034*2 -> 0.068
A23: =IFERROR(INDEX(TENPROFILE,MATCH(B23,MAPROFILE,0)),"") -> Ke góc | B23: ALWS-BK007-1 | D23: 0.05 | E23: 4 | F23: =IFERROR(VLOOKUP(B23,Alu_data,2,0),"") -> 1.231571 | G23: =(1+hp_nhom)*D23*E23*F23 -> 0.26109306 | H23: =gnt -> 98000 | I23: =G23*H23 -> 25587.12
A24: =IFERROR(INDEX(TENPROFILE,MATCH(B24,MAPROFILE,0)),"") -> Ke khung cánh (hệ XingFa) | B24: XF01687 | D24: 0.05 | E24: =4*E18/2 -> 8 | F24: =IFERROR(VLOOKUP(B24,Alu_data,2,0),"") -> 2.064 | G24: =(1+hp_nhom)*D24*E24*F24 -> 0.875136 | H24: =gnt -> 98000 | I24: =G24*H24 -> 85763.328
A26: =IFERROR(INDEX(TENPROFILE,MATCH(B26,MAPROFILE,0)),"") -> Thanh nối khung | B26: WSAW-5009 | C26: W | D26: =INDEX($B$4:$C$11,MATCH(C26,$B$4:$B$11,0),2)-J26 -> 1.19 | E26: 1 | F26: =IFERROR(VLOOKUP(B26,Alu_data,2,0),"") -> 0.211 | G26: =(1+hp_nhom)*D26*E26*F26 -> 0.2661554 | H26: =gnt -> 98000 | I26: =G26*H26 -> 26083.229 | J26: =0.005*2 -> 0.01 | K26: Chia khung
A28: =IFERROR(INDEX(TENPROFILE,MATCH(B28,MAPROFILE,0)),"") -> Khung bao cố định | B28: WSAW-5001 | C28: H2 | D28: =INDEX($B$4:$C$11,MATCH(C28,$B$4:$B$11,0),2)-J28 -> 0.495 | E28: 2 | F28: =IFERROR(VLOOKUP(B28,Alu_data,2,0),"") -> 0.661 | G28: =(1+hp_nhom)*D28*E28*F28 -> 0.6936534 | H28: =gn_csl -> 116300 | I28: =G28*H28 -> 80671.89 | J28: 0.005 | K28: Fix
A29: =IFERROR(INDEX(TENPROFILE,MATCH(B29,MAPROFILE,0)),"") -> Khung bao cố định | B29: WSAW-5001 | C29: W2 | D29: =INDEX($B$4:$C$11,MATCH(C29,$B$4:$B$11,0),2)-J29 -> 1.19 | E29: 2 | F29: =IFERROR(VLOOKUP(B29,Alu_data,2,0),"") -> 0.661 | G29: =(1+hp_nhom)*D29*E29*F29 -> 1.6675708 | H29: =gn_csl -> 116300 | I29: =G29*H29 -> 193938.48 | J29: =0.005*2 -> 0.01
A30: =IFERROR(INDEX(TENPROFILE,MATCH(B30,MAPROFILE,0)),"") -> Nẹp kính | B30: WSAW-5007 | C30: H2 | D30: =INDEX($B$4:$C$11,MATCH(C30,$B$4:$B$11,0),2)-J30 -> 0.453 | E30: =E28 -> 2 | F30: =IFERROR(VLOOKUP(B30,Alu_data,2,0),"") -> 0.225 | G30: =(1+hp_nhom)*D30*E30*F30 -> 0.216081 | H30: =gn_csl -> 116300 | I30: =G30*H30 -> 25130.22 | J30: =0.026+0.021 -> 0.047
A31: =IFERROR(INDEX(TENPROFILE,MATCH(B31,MAPROFILE,0)),"") -> Nẹp kính | B31: WSAW-5007 | C31: W2 | D31: =INDEX($B$4:$C$11,MATCH(C31,$B$4:$B$11,0),2)-J31 -> 1.148 | E31: =E29 -> 2 | F31: =IFERROR(VLOOKUP(B31,Alu_data,2,0),"") -> 0.225 | G31: =(1+hp_nhom)*D31*E31*F31 -> 0.547596 | H31: =gn_csl -> 116300 | I31: =G31*H31 -> 63685.415 | J31: =0.026*2 -> 0.052
A33: =IFERROR(INDEX(TENPROFILE,MATCH(B33,MAPROFILE,0)),"") -> Ke góc | B33: ALWS-BK007-1 | D33: 0.05 | E33: 4 | F33: =IFERROR(VLOOKUP(B33,Alu_data,2,0),"") -> 1.231571 | G33: =(1+hp_nhom)*D33*E33*F33 -> 0.26109306 | H33: =gnt -> 98000 | I33: =G33*H33 -> 25587.12
A72: B. GIÁ VẬT TƯ PHỤ | B72: Mã quy đổi | C72: Đơn vị | D72: Mã BM | I72: =SUBTOTAL(9,I73:I111) -> 148070
A73: =_xlfn.IFNA(INDEX(diengiaivattu,MATCH(B73,mavattu,0),0),0) -> Bơm Foam | B73: foam | C73: =_xlfn.IFNA(INDEX(donvivattu,MATCH(B73,mavattu,0),0),0) -> Mét | E73: =(C6+C7)*2 -> 4.6 | G73: =E73 -> 4.6 | H73: =_xlfn.IFNA(INDEX(dongiavattu,MATCH(B73,mavattu,0),0),0) -> 20000 | I73: =G73*H73 -> 92000
A74: =_xlfn.IFNA(INDEX(diengiaivattu,MATCH(B74,mavattu,0),0),0) -> Ốc vít | B74: OcVit | C74: =_xlfn.IFNA(INDEX(donvivattu,MATCH(B74,mavattu,0),0),0) -> Cái | E74: =15+E23*4+E24*4+ROUNDUP(D19/0.5,0)*E19+ROUNDUP(D26/0.5,0)*E26+E33*4 -> 82 | G74: =E74*(1+hp_vtk) -> 86.1 | H74: =_xlfn.IFNA(INDEX(dongiavattu,MATCH(B74,mavattu,0),0),0) -> 600 | I74: =G74*H74 -> 51660
A75: =_xlfn.IFNA(INDEX(diengiaivattu,MATCH(B75,mavattu,0),0),0) -> Nút bịt nhựa | B75: NutBN | C75: =_xlfn.IFNA(INDEX(donvivattu,MATCH(B75,mavattu,0),0),0) -> Cái | E75: =ROUNDUP(C6/0.5,0)*2 -> 6 | G75: =E75*(1+hp_vtk) -> 6.3 | H75: =_xlfn.IFNA(INDEX(dongiavattu,MATCH(B75,mavattu,0),0),0) -> 700 | I75: =G75*H75 -> 4410
A112: C. GIÁ VẬT TƯ KÍNH | C112: W (m) | D112: H (m) | E112: Tổng diện tích (m2) | F112: Số lượng (tấm) | G112: Ʃ dự trù (m2) | I112: =SUBTOTAL(9,I113:I125) -> 360928.46
A113: =_xlfn.IFNA(INDEX( tenkinh,MATCH(B113,makinh,0),0),"") -> Kính trắng cường lực dày 8mm | B113: =C2 -> k8cl | C113: =(C8-J113)/F113 -> 0.5 | D113: =C9-K113 -> 0.443 | E113: =D113*C113 -> 0.2215 | F113: 2 | G113: =E113*F113*(1+hp_kinh) -> 0.45629 | H113: =_xlfn.IFNA(INDEX(dongiakinh,MATCH(B113,makinh,0),0),0) -> 353703.7 | I113: =G113*H113 -> 161391.46 | J113: =0.081*2+0.038 -> 0.2 | K113: =0.081+0.076 -> 0.157 | L113: =D8 -> Cửa
A114: =_xlfn.IFNA(INDEX( tenkinh,MATCH(B114,makinh,0),0),"") -> Kính trắng cường lực dày 8mm | B114: =C3 -> k8cl | C114: =(C10-J114)/F114 -> 1.132 | D114: =C11-K114 -> 0.437 | E114: =D114*C114 -> 0.494684 | F114: 1 | G114: =E114*F114*(1+hp_kinh) -> 0.50952452 | H114: =_xlfn.IFNA(INDEX(dongiakinh,MATCH(B114,makinh,0),0),0) -> 353703.7 | I114: =G114*H114 -> 180220.71 | J114: =0.034*2 -> 0.068 | K114: =0.034+0.029 -> 0.063 | L114: =D10 -> Fix
A117: =_xlfn.IFNA(INDEX(tenkinh,MATCH(B117,makinh,0),0),0) -> 0
A118: =_xlfn.IFNA(INDEX(tenkinh,MATCH(B118,makinh,0),0),0) -> 0
A119: =_xlfn.IFNA(INDEX(tenkinh,MATCH(B119,makinh,0),0),0) -> 0
A120: =_xlfn.IFNA(INDEX(tenkinh,MATCH(B120,makinh,0),0),0) -> 0
A121: =_xlfn.IFNA(INDEX(tenkinh,MATCH(B121,makinh,0),0),0) -> Băng keo bảo vệ kính | B121: bk | G121: =SUM(G113:G120)*2 -> 1.931629 | H121: =_xlfn.IFNA(INDEX(dongiakinh,MATCH(B121,makinh,0),0),0) -> 10000 | I121: =G121*H121 -> 19316.29
...
